<?xml version="1.0" encoding="UTF-8"?>
<!-- Generated by org.testng.reporters.JUnitXMLReporter -->
<testsuite hostname="WS00CS001" ignored="0" name="test1" tests="8" failures="3" timestamp="20 Mar 2019 14:33:23 GMT" time="0.469" errors="0">
  <testcase name="firstTest" time="0.122" classname="samples.SampleTest"/>
  <testcase name="secondTest" time="0.008" classname="samples.SampleTest">
    <failure type="java.lang.AssertionError" message="expected [1] but found [2]">
      <![CDATA[java.lang.AssertionError: expected [1] but found [2]
at samples.SampleTest.secondTest(SampleTest.java:16)
at java.util.concurrent.FutureTask.run(FutureTask.java:266)
at java.util.concurrent.ThreadPoolExecutor.runWorker(ThreadPoolExecutor.java:1142)
at java.util.concurrent.ThreadPoolExecutor$Worker.run(ThreadPoolExecutor.java:617)
at java.lang.Thread.run(Thread.java:748)
... Removed 22 stack frames]]>
    </failure>
  </testcase> <!-- secondTest -->
  <testcase name="thirdTest" time="0.004" classname="samples.SampleTest"/>
  <testcase name="example1" time="0.005" classname="samples.SecondTestFile">
    <failure type="java.lang.AssertionError" message="This test should be failed expected [3] but found [2]">
      <![CDATA[java.lang.AssertionError: This test should be failed expected [3] but found [2]
at samples.SecondTestFile.example1(SecondTestFile.java:10)
at java.util.concurrent.FutureTask.run(FutureTask.java:266)
at java.util.concurrent.ThreadPoolExecutor.runWorker(ThreadPoolExecutor.java:1142)
at java.util.concurrent.ThreadPoolExecutor$Worker.run(ThreadPoolExecutor.java:617)
at java.lang.Thread.run(Thread.java:748)
... Removed 21 stack frames]]>
    </failure>
  </testcase> <!-- example1 -->
  <testcase name="example2" time="0.003" classname="samples.SecondTestFile"/>
  <testcase name="example3" time="0.004" classname="samples.SecondTestFile"/>
  <testcase name="example4" time="0.004" classname="samples.SecondTestFile">
    <failure type="java.lang.AssertionError" message="This test should be failed">
      <![CDATA[java.lang.AssertionError: This test should be failed
at samples.SecondTestFile.example4(SecondTestFile.java:25)
at java.util.concurrent.FutureTask.run(FutureTask.java:266)
at java.util.concurrent.ThreadPoolExecutor.runWorker(ThreadPoolExecutor.java:1142)
at java.util.concurrent.ThreadPoolExecutor$Worker.run(ThreadPoolExecutor.java:617)
at java.lang.Thread.run(Thread.java:748)
... Removed 17 stack frames]]>
    </failure>
  </testcase> <!-- example4 -->
  <testcase name="skippedByDependencyTest" time="0.0" classname="samples.SecondTestFile">
    <skipped/>
  </testcase> <!-- skippedByDependencyTest -->
</testsuite> <!-- test1 -->
