<?xml version="1.0" encoding="UTF-8"?>
<testng-results skipped="0" failed="1" ignored="1" total="3" passed="1">
  <reporter-output>
  </reporter-output>
  <suite name="Suite1" duration-ms="290" started-at="2019-03-20T14:19:33Z" finished-at="2019-03-20T14:19:33Z">
    <groups>
      <group name="unit">
        <method signature="SampleTest.firstTest()[pri:0, instance:samples.SampleTest@54d18072]" name="firstTest" class="samples.SampleTest"/>
      </group> <!-- unit -->
      <group name="web">
        <method signature="SampleTest.secondTest()[pri:0, instance:samples.SampleTest@54d18072]" name="secondTest" class="samples.SampleTest"/>
      </group> <!-- web -->
    </groups>
    <test name="test2" duration-ms="18" started-at="2019-03-20T14:19:33Z" finished-at="2019-03-20T14:19:33Z">
    </test> <!-- test2 -->
    <test name="test1" duration-ms="290" started-at="2019-03-20T14:19:33Z" finished-at="2019-03-20T14:19:33Z">
      <class name="samples.SampleTest">
        <test-method status="PASS" signature="firstTest()[pri:0, instance:samples.SampleTest@54d18072]" name="firstTest" duration-ms="124" started-at="2019-03-20T14:19:33Z" finished-at="2019-03-20T14:19:33Z">
          <reporter-output>
          </reporter-output>
        </test-method> <!-- firstTest -->
        <test-method status="FAIL" signature="secondTest()[pri:0, instance:samples.SampleTest@54d18072]" name="secondTest" duration-ms="5" started-at="2019-03-20T14:19:33Z" finished-at="2019-03-20T14:19:33Z">
          <exception class="java.lang.AssertionError">
            <message>
              <![CDATA[expected [1] but found [2]]]>
            </message>
            <full-stacktrace>
              <![CDATA[java.lang.AssertionError: expected [1] but found [2]
at org.testng.Assert.fail(Assert.java:96)
at org.testng.Assert.failNotEquals(Assert.java:776)
at org.testng.Assert.assertEqualsImpl(Assert.java:137)
at org.testng.Assert.assertEquals(Assert.java:118)
at org.testng.Assert.assertEquals(Assert.java:453)
at org.testng.Assert.assertEquals(Assert.java:463)
at samples.SampleTest.secondTest(SampleTest.java:16)
at sun.reflect.NativeMethodAccessorImpl.invoke0(Native Method)
at sun.reflect.NativeMethodAccessorImpl.invoke(NativeMethodAccessorImpl.java:62)
at sun.reflect.DelegatingMethodAccessorImpl.invoke(DelegatingMethodAccessorImpl.java:43)
at java.lang.reflect.Method.invoke(Method.java:498)
at org.testng.internal.MethodInvocationHelper.invokeMethod(MethodInvocationHelper.java:124)
at org.testng.internal.Invoker.invokeMethod(Invoker.java:583)
at org.testng.internal.Invoker.invokeTestMethod(Invoker.java:719)
at org.testng.internal.Invoker.invokeTestMethods(Invoker.java:989)
at org.testng.internal.TestMethodWorker.invokeTestMethods(TestMethodWorker.java:125)
at org.testng.internal.TestMethodWorker.run(TestMethodWorker.java:109)
at org.testng.TestRunner.privateRun(TestRunner.java:648)
at org.testng.TestRunner.run(TestRunner.java:505)
at org.testng.SuiteRunner.runTest(SuiteRunner.java:455)
at org.testng.SuiteRunner.access$000(SuiteRunner.java:40)
at org.testng.SuiteRunner$SuiteWorker.run(SuiteRunner.java:489)
at org.testng.internal.thread.ThreadUtil$1.call(ThreadUtil.java:52)
at java.util.concurrent.FutureTask.run(FutureTask.java:266)
at java.util.concurrent.ThreadPoolExecutor.runWorker(ThreadPoolExecutor.java:1142)
at java.util.concurrent.ThreadPoolExecutor$Worker.run(ThreadPoolExecutor.java:617)
at java.lang.Thread.run(Thread.java:748)
]]>
            </full-stacktrace>
          </exception> <!-- java.lang.AssertionError -->
          <reporter-output>
          </reporter-output>
        </test-method> <!-- secondTest -->
      </class> <!-- samples.SampleTest -->
    </test> <!-- test1 -->
  </suite> <!-- Suite1 -->
</testng-results>
